2024-09-19 06:30:03 | INFO    | __main__:stash:131 | run - {'image': '20231121', 'version': '0.10.1.post2', 'role': 'EpicPlayer', 'headless': True}
2024-09-19 06:30:13 | INFO    | __main__:claim_epic_games:97 | Try to flush cookie - {'task': 'claim_epic_games'}
2024-09-19 06:30:15 | INFO    | epic_games.agent:_login:237 | login-with-email - {'url': 'https://www.epicgames.com/id/login?lang=en-US&noHostRedirect=true&redirectUrl=https://store.epicgames.com/en-US/free-games&__cf_chl_rt_tk=V3oq8gNHZcGLXsox7SVHCyHKt_36Nqp33pXbw4tBWcU-1726698614-0.0.1.1-6676'}
2024-09-19 06:30:45 | WARNING    | epic_games.agent:authorize:266 | 执行超时 - {'task': 'authorize', 'retry': 0}
2024-09-19 06:30:46 | INFO    | epic_games.agent:_login:237 | login-with-email - {'url': 'https://www.epicgames.com/id/login?lang=en-US&noHostRedirect=true&redirectUrl=https://store.epicgames.com/en-US/free-games&__cf_chl_rt_tk=LnGApgbXBmoLXBstawfHPK2AwrB1qe7.6jVcb_kJFaw-1726698646-0.0.1.1-6633'}
2024-09-19 06:31:16 | WARNING    | epic_games.agent:authorize:266 | 执行超时 - {'task': 'authorize', 'retry': 1}
2024-09-19 06:31:17 | INFO    | epic_games.agent:_login:237 | login-with-email - {'url': 'https://www.epicgames.com/id/login?lang=en-US&noHostRedirect=true&redirectUrl=https://store.epicgames.com/en-US/free-games&__cf_chl_rt_tk=3MWMnpn9S.VtwRSMbX1VE1Dk0hN.ueo3E7NBD9QsME4-1726698677-0.0.1.1-6655'}
2024-09-19 06:31:47 | WARNING    | epic_games.agent:authorize:266 | 执行超时 - {'task': 'authorize', 'retry': 2}
2024-09-19 06:31:47 | ERROR    | __main__:run:158 | An error has been caught in function 'run', process 'MainProcess' (3649), thread 'MainThread' (139837590276992): - {}
Traceback (most recent call last):
  File "/home/runner/work/epic-action/epic-action/epic/src/claim.py", line 162, in <module>
    asyncio.run(run())
  File "/opt/hostedtoolcache/Python/3.10.15/x64/lib/python3.10/asyncio/runners.py", line 44, in run
    return loop.run_until_complete(main)
  File "/opt/hostedtoolcache/Python/3.10.15/x64/lib/python3.10/asyncio/base_events.py", line 636, in run_until_complete
    self.run_forever()
  File "/opt/hostedtoolcache/Python/3.10.15/x64/lib/python3.10/asyncio/base_events.py", line 603, in run_forever
    self._run_once()
  File "/opt/hostedtoolcache/Python/3.10.15/x64/lib/python3.10/asyncio/base_events.py", line 1909, in _run_once
    handle._run()
  File "/opt/hostedtoolcache/Python/3.10.15/x64/lib/python3.10/asyncio/events.py", line 80, in _run
    self._context.run(self._callback, *self._args)
> File "/home/runner/work/epic-action/epic-action/epic/src/claim.py", line 158, in run
    await agent.stash()
  File "/home/runner/work/epic-action/epic-action/epic/src/claim.py", line 151, in stash
    await self.claim_epic_games(context)
  File "/home/runner/work/epic-action/epic-action/epic/src/claim.py", line 98, in claim_epic_games
    if await epic.authorize(page):
  File "/home/runner/work/epic-action/epic-action/epic/src/epic_games/agent.py", line 269, in authorize
    raise RuntimeError(f"Failed to flush token - agent={self.__class__.__name__}")
RuntimeError: Failed to flush token - agent=EpicGames
